<mujoco model="arm_6dof">
  <option timestep="0.002" gravity="0 0 -9.81"/>

  <worldbody>
    <light diffuse=".5 .5 .5" pos="0 0 3" dir="0 0 -1"/>
    <geom type="plane" size="2 2 0.1" rgba=".9 .9 .9 1"/>

    <body name="link1" pos="0 0 0.1">
      <joint name="joint1" type="hinge" axis="0 0 1"
             range="-3.14 3.14"/>
      <geom type="cylinder" size="0.05 0.15" rgba=".8 .2 .2 1"/>

      <body name="link2" pos="0 0 0.3">
        <joint name="joint2" type="hinge" axis="0 1 0"
               range="-1.57 1.57"/>
        <geom type="cylinder" size="0.04 0.12" rgba=".2 .8 .2 1"/>

        <body name="link3" pos="0 0 0.25">
          <joint name="joint3" type="hinge" axis="0 1 0"
                 range="-1.57 1.57"/>
          <geom type="cylinder" size="0.035 0.1" rgba=".2 .2 .8 1"/>

          <body name="link4" pos="0 0 0.2">
            <joint name="joint4" type="hinge" axis="0 0 1"
                   range="-3.14 3.14"/>
            <geom type="cylinder" size="0.03 0.08" rgba=".8 .8 .2 1"/>

            <body name="link5" pos="0 0 0.15">
              <joint name="joint5" type="hinge" axis="0 1 0"
                     range="-1.57 1.57"/>
              <geom type="cylinder" size="0.025 0.07" rgba=".8 .2 .8 1"/>

              <body name="link6" pos="0 0 0.12">
                <joint name="joint6" type="hinge" axis="0 0 1"
                       range="-3.14 3.14"/>
                <geom type="cylinder" size="0.02 0.05" rgba=".2 .8 .8 1"/>
              </body>
            </body>
          </body>
        </body>
      </body>
    </body>
  </worldbody>

  <actuator>
    <motor joint="joint1" gear="100" ctrlrange="-5 5"/>
    <motor joint="joint2" gear="80"  ctrlrange="-5 5"/>
    <motor joint="joint3" gear="60"  ctrlrange="-5 5"/>
    <motor joint="joint4" gear="50"  ctrlrange="-5 5"/>
    <motor joint="joint5" gear="40"  ctrlrange="-5 5"/>
    <motor joint="joint6" gear="30"  ctrlrange="-5 5"/>
  </actuator>
</mujoco>
